Workbook
Name dateColumn_Reminder_1612459588747: Customers!$J$1

Sheet Product2
A1: =#REF! -> #REF! | B1: =#REF! -> #REF! | C1: =#REF! -> #REF! | D1: =#REF! -> #REF! | E1: =#REF! -> #REF! | F1: =#REF! -> #REF! | G1: =#REF! -> #REF! | H1: =#REF! -> #REF! | ... S1: =#REF! -> #REF! | T1: Custom Paper | AE1: UV Crystal | AF1: UV Flat | AG1: =#REF! -> #REF! | AH1: =#REF! -> #REF! | AI1: =#REF! -> #REF! | AJ1: =#REF! -> #REF! | AK1: =#REF! -> #REF! | AL1: =#REF! -> #REF! | AM1: =#REF! -> #REF! | AN1: Plain | AO1: Gumming Full | AP1: Gumming Top Bottom | AQ1: Gumming 4 Sides | AR1: Dangler Making | AS1: Dangler With Rivet | AT1: Dangler With Rivet and Elastic | AU1: Half Cut Front | AV1: Half Cut Back | AW1: Cutting | AX1: Plain | AY1: Custom Gumming | AZ1: Carry Bag Single Pasting | BA1: Carry Bag Double Pasting | BE1: =Quotation!A29 -> Offset | BF1: =Quotation!B29 -> Packaging | BG1: =Quotation!B31 -> Custom Paper | BH1: =Quotation!B32 -> Varnish | BI1: =Quotation!C34 -> Carry Bag Single Pasting | BJ1: =Quotation!C35 -> Plain | BK1: =Quotation!B35 -> Plain | BL1: =Quotation!A34 -> New Job | BO1: =Quotation!B31 -> Custom Paper | BS1: =Quotation!B31 -> Custom Paper | BZ1: =Quotation!C31 -> Custom | CD1: =Quotation!D31 -> GSM
A2: =#REF! -> #REF! | B2: =#REF! -> #REF! | C2: =#REF! -> #REF! | D2: =#REF! -> #REF! | E2: =#REF! -> #REF! | F2: =#REF! -> #REF! | G2: =Quotation!C31 -> Custom | H2: =Quotation!E30 -> 500 | I2: =#REF! -> #REF! | J2: =#REF! -> #REF! | K2: =J2 -> #REF! | L2: =J2 -> #REF! | M2: =J2 -> #REF! | N2: =J2 -> #REF! | O2: =#REF! -> #REF! | P2: =#REF! -> #REF! | Q2: =#REF! -> #REF! | R2: =#REF! -> #REF! | S2: =#REF! -> #REF! | T2: =#REF! -> #REF! | AE2: =#REF! -> #REF! | AF2: =#REF! -> #REF! | AG2: =#REF! -> #REF! | AH2: =#REF! -> #REF! | AI2: =#REF! -> #REF! | AJ2: =#REF! -> #REF! | AK2: =#REF! -> #REF! | AL2: =#REF! -> #REF! | AM2: =#REF! -> #REF! | AN2: 0 | AO2: =#REF! -> #REF! | AP2: =#REF! -> #REF! | AQ2: =#REF! -> #REF! | AR2: =#REF! -> #REF! | AS2: =#REF! -> #REF! | AT2: =#REF! -> #REF! | AU2: =#REF! -> #REF! | AV2: =#REF! -> #REF! | AW2: =#REF! -> #REF! | AX2: 0 | AY2: =#REF! -> #REF! | AZ2: =#REF! -> #REF! | BA2: =#REF! -> #REF! | BS2: =IF(BS1="","","and BS = '"&BS1&"'") -> and BS = 'Custom Paper' | BZ2: =IF(BZ1="","","and BX = '"&BZ1&"'") -> and BX = 'Custom' | CD2: =IF(CD1="","","and CD = '"&CD1&"'") -> and CD = 'GSM'
A3: =A1 -> #REF! | B3: =B1 -> #REF! | C3: =C1 -> #REF! | D3: =D1 -> #REF! | E3: =E1 -> #REF! | F3: =F1 -> #REF! | G3: =G1 -> #REF! | H3: =H1 -> #REF! | ... S3: =S1 -> #REF! | T3: Custom Paper | AE3: UV Crystal | AF3: UV Flat | AG3: =AG1 -> #REF! | AH3: =AH1 -> #REF! | AI3: =AI1 -> #REF! | AJ3: =AJ1 -> #REF! | AK3: =AK1 -> #REF! | AL3: =AL1 -> #REF! | AM3: =AM1 -> #REF! | AN3: =AN1 -> Plain | AO3: Gumming Full | AP3: Gumming Top Bottom | AQ3: Gumming 4 Sides | AR3: Dangler Making | AS3: Dangler With Rivet | AT3: Dangler With Rivet and Elastic | AU3: Half Cut Front | AV3: Half Cut Back | AW3: Cutting | AX3: Plain | AY3: Custom Gumming | AZ3: Carry Bag Single Pasting | BA3: Carry Bag Double Pasting | BE3: =IF(BE1="","","and A = '"&BE1&"'") -> and A = 'Offset' | BF3: =IF(BF1="","","and B = '"&BF1&"'") -> and B = 'Packaging' | BG3: =IF(BF1="","","and M = '"&BF1&"'") -> and M = 'Packaging' | BH3: =IF(BF1="","","and BF = '"&BF1&"'") -> and BF = 'Packaging' | BI3: =IF(BG1="","","and AY = '"&BG1&"'") -> and AY = 'Custom Paper' | BJ3: =IF(BH1="","","and BC = '"&BH1&"'") -> and BC = 'Varnish' | BK3: =IF(BI1="","","and AW = '"&BI1&"'") -> and AW = 'Carry Bag Single Pasting' | BL3: =IF(BJ1="","","and AU = '"&BJ1&"'") -> and AU = 'Plain' | BM3: =IF(BK1="","","and BC = '"&BK1&"'") -> and BC = 'Plain' | BN3: =IF(BL1="","","and BA = '"&BL1&"'") -> and BA = 'New Job' | BO3: =IF(BO1="","","and AW = '"&BO1&"'") -> and AW = 'Custom Paper' | BS3: =CONCATENATE("select * where 1=1",BS2) -> select * where 1=1and BS = 'Custom Paper' | BZ3: =CONCATENATE("select * where 1=1",BZ2) -> select * where 1=1and BX = 'Custom' | CD3: =CONCATENATE("select * where 1=1",CD2) -> select * where 1=1and CD = 'GSM'
A4: =#REF! -> #REF! | B4: =#REF! -> #REF! | C4: =#REF! -> #REF! | D4: =#REF! -> #REF! | E4: =#REF! -> #REF! | F4: =#REF! -> #REF! | G4: =G2 -> Custom | H4: =Quotation!E31 -> 35000 | I4: =#REF! -> #REF! | J4: =#REF! -> #REF! | K4: =J4 -> #REF! | L4: =J4 -> #REF! | M4: =J4 -> #REF! | N4: =J4 -> #REF! | O4: =#REF! -> #REF! | P4: =#REF! -> #REF! | Q4: =#REF! -> #REF! | R4: =#REF! -> #REF! | S4: =#REF! -> #REF! | T4: =#REF! -> #REF! | AE4: =#REF! -> #REF! | AF4: =#REF! -> #REF! | AG4: =#REF! -> #REF! | AH4: =#REF! -> #REF! | AI4: =#REF! -> #REF! | AJ4: =#REF! -> #REF! | AK4: =#REF! -> #REF! | AL4: =#REF! -> #REF! | AM4: =#REF! -> #REF! | AN4: 0 | AO4: =#REF! -> #REF! | AP4: =#REF! -> #REF! | AQ4: =#REF! -> #REF! | AR4: =#REF! -> #REF! | AS4: =#REF! -> #REF! | AT4: =#REF! -> #REF! | AU4: =#REF! -> #REF! | AV4: =#REF! -> #REF! | AW4: =#REF! -> #REF! | AX4: 0 | AY4: =#REF! -> #REF! | AZ4: =#REF! -> #REF! | BA4: =#REF! -> #REF! | BE4: =CONCATENATE("select * where 1=1",BE3) -> select * where 1=1and A = 'Offset' | BF4: =CONCATENATE("select * where 1=1",BF3) -> select * where 1=1and B = 'Packaging' | BG4: =CONCATENATE("select * where 1=1",BG3) -> select * where 1=1and M = 'Packaging' | BH4: =CONCATENATE("select * where 1=1",BH3) -> select * where 1=1and BF = 'Packaging' | BI4: =CONCATENATE("select * where 1=1",BI3) -> select * where 1=1and AY = 'Custom Paper' | BJ4: =CONCATENATE("select * where 1=1",BJ3) -> select * where 1=1and BC = 'Varnish' | BK4: =CONCATENATE("select * where 1=1",BK3) -> select * where 1=1and AW = 'Carry Bag Single Pasting' | BL4: =CONCATENATE("select * where 1=1",BL3) -> select * where 1=1and AU = 'Plain' | ... BO4: =CONCATENATE("select * where 1=1",BO3) -> select * where 1=1and AW = 'Custom Paper' | BX4: N/A | BY4: N/A | CD4: GSM | CE4: =Quotation!D32 -> 170
A5: =A1 -> #REF! | B5: =B1 -> #REF! | C5: =C1 -> #REF! | D5: =D1 -> #REF! | E5: =E1 -> #REF! | F5: =F1 -> #REF! | G5: =G1 -> #REF! | H5: =H1 -> #REF! | ... S5: =S1 -> #REF! | T5: Custom Paper | AE5: UV Crystal | AF5: UV Flat | AG5: =AG1 -> #REF! | AH5: =AH1 -> #REF! | AI5: =AI1 -> #REF! | AJ5: =AJ1 -> #REF! | AK5: =AK1 -> #REF! | AL5: =AL1 -> #REF! | AM5: =AM1 -> #REF! | AN5: =AN1 -> Plain | AO5: Gumming Full | AP5: Gumming Top Bottom | AQ5: Gumming 4 Sides | AR5: Dangler Making | AS5: Dangler With Rivet | AT5: Dangler With Rivet and Elastic | AU5: Half Cut Front | AV5: Half Cut Back | AW5: Cutting | AX5: Plain | AY5: Custom Gumming | AZ5: Carry Bag Single Pasting | BA5: Carry Bag Double Pasting | BD5: All | BJ5: Plain | BP5: Plain | BQ5: N/A | BS5: SBS | BT5: ITC | BU5: 230 GSM | BV5: =#REF! -> #REF! | BW5: =IFERROR(__xludf.DUMMYFUNCTION("QUERY(BS5:BV60,BS3)"),"Custom Paper") -> Custom Paper | BX5: =IFERROR(__xludf.DUMMYFUNCTION("""COMPUTED_VALUE"""),"Custom") -> Custom | BZ5: =IFERROR(__xludf.DUMMYFUNCTION("""COMPUTED_VALUE"""),75) -> 75 | CA5: =IFERROR(__xludf.DUMMYFUNCTION("(QUERY(BX5:BZ42,BZ3))"),"Custom") -> Custom | CC5: =IFERROR(__xludf.DUMMYFUNCTION("""COMPUTED_VALUE"""),75) -> 75 | CD5: =BY5 -> 0 | CE5: =CD5 -> 0 | CF5: =IFERROR(__xludf.DUMMYFUNCTION("QUERY(CD4:CE42,CD3)"),"GSM") -> GSM | CG5: =IFERROR(__xludf.DUMMYFUNCTION("""COMPUTED_VALUE"""),"170") -> 170
A6: =#REF! -> #REF! | B6: =#REF! -> #REF! | C6: =#REF! -> #REF! | D6: =#REF! -> #REF! | E6: =#REF! -> #REF! | F6: =#REF! -> #REF! | G6: =G2 -> Custom | H6: =Quotation!E32 -> 0 | I6: =#REF! -> #REF! | J6: =#REF! -> #REF! | K6: =J6 -> #REF! | L6: =J6 -> #REF! | M6: =J6 -> #REF! | N6: =J6 -> #REF! | O6: =#REF! -> #REF! | P6: =#REF! -> #REF! | Q6: =#REF! -> #REF! | R6: =#REF! -> #REF! | S6: =#REF! -> #REF! | T6: =#REF! -> #REF! | AE6: =#REF! -> #REF! | AF6: =#REF! -> #REF! | AG6: =#REF! -> #REF! | AH6: =#REF! -> #REF! | AI6: =#REF! -> #REF! | AJ6: =#REF! -> #REF! | AK6: =#REF! -> #REF! | AL6: =#REF! -> #REF! | AM6: =#REF! -> #REF! | AN6: 0 | AO6: =#REF! -> #REF! | AP6: =#REF! -> #REF! | AQ6: =#REF! -> #REF! | AR6: =#REF! -> #REF! | AS6: =#REF! -> #REF! | AT6: =#REF! -> #REF! | AU6: =#REF! -> #REF! | AV6: =#REF! -> #REF! | AW6: =#REF! -> #REF! | AX6: 0 | AY6: =#REF! -> #REF! | AZ6: =#REF! -> #REF! | BA6: =#REF! -> #REF! | BC6: =IFERROR(__xludf.DUMMYFUNCTION("UNIQUE(QUERY(Item!M1:N2457,BG4))"),"Packaging") -> Packaging | BD6: =IFERROR(__xludf.DUMMYFUNCTION("""COMPUTED_VALUE"""),"Agarbatti") -> Agarbatti | BE6: =IFERROR(__xludf.DUMMYFUNCTION("UNIQUE(QUERY(Item!A2:B2457,BE4))"),"Offset") -> Offset | BF6: =IFERROR(__xludf.DUMMYFUNCTION("""COMPUTED_VALUE"""),"Packaging") -> Packaging | BG6: =IFERROR(__xludf.DUMMYFUNCTION("UNIQUE(QUERY(Item!A2:L2457,BF4))"),"Offset") -> Offset | BH6: =IFERROR(__xludf.DUMMYFUNCTION("""COMPUTED_VALUE"""),"Packaging") -> Packaging | BI6: =IFERROR(__xludf.DUMMYFUNCTION("""COMPUTED_VALUE"""),"SBS") -> SBS | BJ6: =IFERROR(__xludf.DUMMYFUNCTION("""COMPUTED_VALUE"""),"Carry Bag Single Pasting") -> Carry Bag Single Pasting | BK6: =IFERROR(__xludf.DUMMYFUNCTION("""COMPUTED_VALUE"""),"Lamination Thermal") -> Lamination Thermal | BL6: =IFERROR(__xludf.DUMMYFUNCTION("""COMPUTED_VALUE"""),"Single Colour") -> Single Colour | BM6: =IFERROR(__xludf.DUMMYFUNCTION("""COMPUTED_VALUE"""),1) -> 1 | BN6: =IFERROR(__xludf.DUMMYFUNCTION("""COMPUTED_VALUE"""),1926) -> 1926 | BO6: =IFERROR(__xludf.DUMMYFUNCTION("""COMPUTED_VALUE"""),"New Job") -> New Job | BP6: =IFERROR(__xludf.DUMMYFUNCTION("""COMPUTED_VALUE"""),"Leafing") -> Leafing | BQ6: =IFERROR(__xludf.DUMMYFUNCTION("""COMPUTED_VALUE"""),"Yes") -> Yes | BR6: =IFERROR(__xludf.DUMMYFUNCTION("""COMPUTED_VALUE"""),"Normal") -> Normal | BS6: SBS | BT6: Century | BU6: 250 GSM | BV6: =#REF! -> #REF! | CD6: =BY6 -> 0 | CE6: =CD6 -> 0
A7: Type | B7: =Quotation!A29 -> Offset | F7: =IF(B8="","","and Q = '"&B8&"'") -> and Q = 'Packaging' | AV7: =#REF! -> #REF! | BC7: =IFERROR(__xludf.DUMMYFUNCTION("""COMPUTED_VALUE"""),"Packaging") -> Packaging | BD7: =IFERROR(__xludf.DUMMYFUNCTION("""COMPUTED_VALUE"""),"Apparel") -> Apparel | BE7: =IFERROR(__xludf.DUMMYFUNCTION("""COMPUTED_VALUE"""),"Offset") -> Offset | BF7: =IFERROR(__xludf.DUMMYFUNCTION("""COMPUTED_VALUE"""),"Commercial") -> Commercial | BG7: =IFERROR(__xludf.DUMMYFUNCTION("""COMPUTED_VALUE"""),"Offset") -> Offset | BH7: =IFERROR(__xludf.DUMMYFUNCTION("""COMPUTED_VALUE"""),"Packaging") -> Packaging | BI7: =IFERROR(__xludf.DUMMYFUNCTION("""COMPUTED_VALUE"""),"WhiteBack") -> WhiteBack | BJ7: =IFERROR(__xludf.DUMMYFUNCTION("""COMPUTED_VALUE"""),"Carry Bag Double Pasting") -> Carry Bag Double Pasting | BK7: =IFERROR(__xludf.DUMMYFUNCTION("""COMPUTED_VALUE"""),"Lamination Normal Gloss") -> Lamination Normal Gloss | BL7: =IFERROR(__xludf.DUMMYFUNCTION("""COMPUTED_VALUE"""),"Double Colour") -> Double Colour | BM7: =IFERROR(__xludf.DUMMYFUNCTION("""COMPUTED_VALUE"""),2) -> 2 | BN7: =IFERROR(__xludf.DUMMYFUNCTION("""COMPUTED_VALUE"""),2029) -> 2029 | BO7: =IFERROR(__xludf.DUMMYFUNCTION("""COMPUTED_VALUE"""),"Repeat Job") -> Repeat Job | BP7: =IFERROR(__xludf.DUMMYFUNCTION("""COMPUTED_VALUE"""),"Leafing") -> Leafing | BQ7: =IFERROR(__xludf.DUMMYFUNCTION("""COMPUTED_VALUE"""),"N/A") -> N/A | BR7: =IFERROR(__xludf.DUMMYFUNCTION("""COMPUTED_VALUE"""),"Normal") -> Normal | BS7: SBS | BT7: Normal | BU7: 280 GSM | BV7: =#REF! -> #REF! | CD7: =BY7 -> 0 | CE7: =CD7 -> 0
A8: Sub Type | B8: =Quotation!B29 -> Packaging | F8: =IF(B7="","","and P = '"&B7&"'") -> and P = 'Offset' | BC8: =IFERROR(__xludf.DUMMYFUNCTION("""COMPUTED_VALUE"""),"Packaging") -> Packaging | BD8: =IFERROR(__xludf.DUMMYFUNCTION("""COMPUTED_VALUE"""),"Artsbury") -> Artsbury | BE8: =IFERROR(__xludf.DUMMYFUNCTION("""COMPUTED_VALUE"""),"Offset") -> Offset | BF8: =IFERROR(__xludf.DUMMYFUNCTION("""COMPUTED_VALUE"""),"Booklet") -> Booklet | BG8: =IFERROR(__xludf.DUMMYFUNCTION("""COMPUTED_VALUE"""),"Offset") -> Offset | BH8: =IFERROR(__xludf.DUMMYFUNCTION("""COMPUTED_VALUE"""),"Packaging") -> Packaging | BI8: =IFERROR(__xludf.DUMMYFUNCTION("""COMPUTED_VALUE"""),"GreyBack") -> GreyBack | BJ8: =IFERROR(__xludf.DUMMYFUNCTION("""COMPUTED_VALUE"""),"Plain") -> Plain | BK8: =IFERROR(__xludf.DUMMYFUNCTION("""COMPUTED_VALUE"""),"Lamination Normal Matt") -> Lamination Normal Matt | BL8: =IFERROR(__xludf.DUMMYFUNCTION("""COMPUTED_VALUE"""),"Four Colour") -> Four Colour | BM8: =IFERROR(__xludf.DUMMYFUNCTION("""COMPUTED_VALUE"""),4) -> 4 | BN8: =IFERROR(__xludf.DUMMYFUNCTION("""COMPUTED_VALUE"""),2840) -> 2840 | BO8: =IFERROR(__xludf.DUMMYFUNCTION("""COMPUTED_VALUE"""),"New Job") -> New Job | BP8: =IFERROR(__xludf.DUMMYFUNCTION("""COMPUTED_VALUE"""),"Leafing") -> Leafing | BQ8: =IFERROR(__xludf.DUMMYFUNCTION("""COMPUTED_VALUE"""),"Yes") -> Yes | BR8: =IFERROR(__xludf.DUMMYFUNCTION("""COMPUTED_VALUE"""),"Normal") -> Normal | BS8: SBS | BT8: Custom | BU8: 300 GSM | BV8: =Quotation!$C$29 -> 75 | CD8: =BY8 -> 0 | CE8: =CD8 -> 0
A9: Select Category | B9: =Quotation!A30 -> Food | D9: =IF(B12="All","","and B = '"&B12&"'") -> and B = '' | F9: =IF(B9="All","","and B = '"&B9&"'") -> and B = 'Food' | BC9: =IFERROR(__xludf.DUMMYFUNCTION("""COMPUTED_VALUE"""),"Packaging") -> Packaging | BD9: =IFERROR(__xludf.DUMMYFUNCTION("""COMPUTED_VALUE"""),"Aryan") -> Aryan | BG9: =IFERROR(__xludf.DUMMYFUNCTION("""COMPUTED_VALUE"""),"Offset") -> Offset | BH9: =IFERROR(__xludf.DUMMYFUNCTION("""COMPUTED_VALUE"""),"Packaging") -> Packaging | BI9: =IFERROR(__xludf.DUMMYFUNCTION("""COMPUTED_VALUE"""),"Duplex") -> Duplex | BJ9: =IFERROR(__xludf.DUMMYFUNCTION("""COMPUTED_VALUE"""),"Plain") -> Plain | BK9: =IFERROR(__xludf.DUMMYFUNCTION("""COMPUTED_VALUE"""),"Varnish") -> Varnish | BL9: =IFERROR(__xludf.DUMMYFUNCTION("""COMPUTED_VALUE"""),"Four + One Colour") -> Four + One Colour | BM9: =IFERROR(__xludf.DUMMYFUNCTION("""COMPUTED_VALUE"""),6.75) -> 6.75 | BN9: =IFERROR(__xludf.DUMMYFUNCTION("""COMPUTED_VALUE"""),1926) -> 1926 | BO9: =IFERROR(__xludf.DUMMYFUNCTION("""COMPUTED_VALUE"""),"Repeat Job") -> Repeat Job | BP9: =IFERROR(__xludf.DUMMYFUNCTION("""COMPUTED_VALUE"""),"Leafing") -> Leafing | BQ9: =IFERROR(__xludf.DUMMYFUNCTION("""COMPUTED_VALUE"""),"N/A") -> N/A | BR9: =IFERROR(__xludf.DUMMYFUNCTION("""COMPUTED_VALUE"""),"Normal") -> Normal | BS9: SBS | BT9: Custom | BU9: 330 GSM | BV9: =$BV$8 -> 75 | CD9: =BY9 -> 0 | CE9: =CD9 -> 0
B10: =Quotation!A31 -> Wrap | D10: =IF(B10="","","and T = '"&B10&"'") -> and T = 'Wrap' | F10: =IF(B10="","","and C = '"&B10&"'") -> and C = 'Wrap' | I10: =CONCATENATE("select * where 1=1",F9,F10,F11) -> select * where 1=1and B = 'Food'and C = 'Wrap'and D = '240*64*160 mm | 9.5*2.5*6.25 inch' | BC10: =IFERROR(__xludf.DUMMYFUNCTION("""COMPUTED_VALUE"""),"Packaging") -> Packaging | BD10: =IFERROR(__xludf.DUMMYFUNCTION("""COMPUTED_VALUE"""),"Atta") -> Atta | BG10: =IFERROR(__xludf.DUMMYFUNCTION("""COMPUTED_VALUE"""),"Offset") -> Offset | BH10: =IFERROR(__xludf.DUMMYFUNCTION("""COMPUTED_VALUE"""),"Packaging") -> Packaging | BI10: =IFERROR(__xludf.DUMMYFUNCTION("""COMPUTED_VALUE"""),"Custom Paper") -> Custom Paper | BJ10: =IFERROR(__xludf.DUMMYFUNCTION("""COMPUTED_VALUE"""),"Plain") -> Plain | BK10: =IFERROR(__xludf.DUMMYFUNCTION("""COMPUTED_VALUE"""),"UV Hybrid") -> UV Hybrid | BL10: =IFERROR(__xludf.DUMMYFUNCTION("""COMPUTED_VALUE"""),"Four + Two Colour") -> Four + Two Colour | BM10: =IFERROR(__xludf.DUMMYFUNCTION("""COMPUTED_VALUE"""),7.75) -> 7.75 | BN10: =IFERROR(__xludf.DUMMYFUNCTION("""COMPUTED_VALUE"""),1926) -> 1926 | BO10: =IFERROR(__xludf.DUMMYFUNCTION("""COMPUTED_VALUE"""),"New Job") -> New Job | BP10: =IFERROR(__xludf.DUMMYFUNCTION("""COMPUTED_VALUE"""),"Leafing") -> Leafing | BQ10: =IFERROR(__xludf.DUMMYFUNCTION("""COMPUTED_VALUE"""),"Yes") -> Yes | BR10: =IFERROR(__xludf.DUMMYFUNCTION("""COMPUTED_VALUE"""),"Normal") -> Normal | BS10: WhiteBack | BT10: Khanna | BU10: 230 GSM | BV10: =#REF! -> #REF! | CD10: =BY10 -> 0 | CE10: =CD10 -> 0
A11: Select Size | B11: =Quotation!B30 -> 240*64*160 mm | 9.5*2.5*6.25 inch | D11: =IF(B11="","","and AM = '"&B11&"'") -> and AM = '240*64*160 mm | 9.5*2.5*6.25 inch' | F11: =IF(B11="","","and D = '"&B11&"'") -> and D = '240*64*160 mm | 9.5*2.5*6.25 inch' | I11: =CONCATENATE("select * where 1=1",F10) -> select * where 1=1and C = 'Wrap' | BC11: =IFERROR(__xludf.DUMMYFUNCTION("""COMPUTED_VALUE"""),"Packaging") -> Packaging | BD11: =IFERROR(__xludf.DUMMYFUNCTION("""COMPUTED_VALUE"""),"Bakery") -> Bakery | BG11: =IFERROR(__xludf.DUMMYFUNCTION("""COMPUTED_VALUE"""),"Offset") -> Offset | BH11: =IFERROR(__xludf.DUMMYFUNCTION("""COMPUTED_VALUE"""),"Packaging") -> Packaging | BI11: =IFERROR(__xludf.DUMMYFUNCTION("""COMPUTED_VALUE"""),"Other Type") -> Other Type | BJ11: =IFERROR(__xludf.DUMMYFUNCTION("""COMPUTED_VALUE"""),"Plain") -> Plain | BK11: =IFERROR(__xludf.DUMMYFUNCTION("""COMPUTED_VALUE"""),"UV Flat") -> UV Flat | BL11: =IFERROR(__xludf.DUMMYFUNCTION("""COMPUTED_VALUE"""),"Four + Four Colour") -> Four + Four Colour | BM11: =IFERROR(__xludf.DUMMYFUNCTION("""COMPUTED_VALUE"""),9.75) -> 9.75 | BN11: =IFERROR(__xludf.DUMMYFUNCTION("""COMPUTED_VALUE"""),1926) -> 1926 | BO11: =IFERROR(__xludf.DUMMYFUNCTION("""COMPUTED_VALUE"""),"Repeat Job") -> Repeat Job | BP11: =IFERROR(__xludf.DUMMYFUNCTION("""COMPUTED_VALUE"""),"Leafing") -> Leafing | BQ11: =IFERROR(__xludf.DUMMYFUNCTION("""COMPUTED_VALUE"""),"N/A") -> N/A | BR11: =IFERROR(__xludf.DUMMYFUNCTION("""COMPUTED_VALUE"""),"Normal") -> Normal | BS11: WhiteBack | BT11: Sinar Mas | BU11: 250 GSM | BV11: =#REF! -> #REF! | CD11: =BY11 -> 0 | CE11: =CD11 -> 0
D12: =CONCATENATE("select * where 1=1",D11) -> select * where 1=1and AM = '240*64*160 mm | 9.5*2.5*6.25 inch' | F12: =CONCATENATE("select * where 1=1",F9,F8,F7) -> select * where 1=1and B = 'Food'and P = 'Offset'and Q = 'Packaging' | I12: =CONCATENATE("select * where 1=1",F11,F10) -> select * where 1=1and D = '240*64*160 mm | 9.5*2.5*6.25 inch'and C = 'Wrap' | BC12: =IFERROR(__xludf.DUMMYFUNCTION("""COMPUTED_VALUE"""),"Packaging") -> Packaging | BD12: =IFERROR(__xludf.DUMMYFUNCTION("""COMPUTED_VALUE"""),"Bakery Online") -> Bakery Online | BG12: =IFERROR(__xludf.DUMMYFUNCTION("""COMPUTED_VALUE"""),"Offset") -> Offset | BH12: =IFERROR(__xludf.DUMMYFUNCTION("""COMPUTED_VALUE"""),"Packaging") -> Packaging | BI12: =IFERROR(__xludf.DUMMYFUNCTION("""COMPUTED_VALUE"""),"Other Type") -> Other Type | BJ12: =IFERROR(__xludf.DUMMYFUNCTION("""COMPUTED_VALUE"""),"Plain") -> Plain | BK12: =IFERROR(__xludf.DUMMYFUNCTION("""COMPUTED_VALUE"""),"Spot UV") -> Spot UV | BL12: =IFERROR(__xludf.DUMMYFUNCTION("""COMPUTED_VALUE"""),"Without Print") -> Without Print | BM12: =IFERROR(__xludf.DUMMYFUNCTION("""COMPUTED_VALUE"""),0) -> 0 | BN12: =IFERROR(__xludf.DUMMYFUNCTION("""COMPUTED_VALUE"""),1926) -> 1926 | BO12: =IFERROR(__xludf.DUMMYFUNCTION("""COMPUTED_VALUE"""),"New Job") -> New Job | BP12: =IFERROR(__xludf.DUMMYFUNCTION("""COMPUTED_VALUE"""),"Leafing") -> Leafing | BQ12: =IFERROR(__xludf.DUMMYFUNCTION("""COMPUTED_VALUE"""),"Yes") -> Yes | BR12: =IFERROR(__xludf.DUMMYFUNCTION("""COMPUTED_VALUE"""),"Normal") -> Normal | BS12: WhiteBack | BT12: Normal | BU12: 280 GSM | BV12: =#REF! -> #REF! | CD12: =BY12 -> 0 | CE12: =CD12 -> 0
A13: =IFERROR(__xludf.DUMMYFUNCTION("QUERY(AJ15:AY2457,$D$12,0)"),"#N/A") -> #N/A | BC13: =IFERROR(__xludf.DUMMYFUNCTION("""COMPUTED_VALUE"""),"Packaging") -> Packaging | BD13: =IFERROR(__xludf.DUMMYFUNCTION("""COMPUTED_VALUE"""),"Beverages") -> Beverages | BG13: =IFERROR(__xludf.DUMMYFUNCTION("""COMPUTED_VALUE"""),"Offset") -> Offset | BH13: =IFERROR(__xludf.DUMMYFUNCTION("""COMPUTED_VALUE"""),"Packaging") -> Packaging | BI13: =IFERROR(__xludf.DUMMYFUNCTION("""COMPUTED_VALUE"""),"Other Type") -> Other Type | BJ13: =IFERROR(__xludf.DUMMYFUNCTION("""COMPUTED_VALUE"""),"Plain") -> Plain | BK13: =IFERROR(__xludf.DUMMYFUNCTION("""COMPUTED_VALUE"""),"UV Crystal") -> UV Crystal | BL13: =IFERROR(__xludf.DUMMYFUNCTION("""COMPUTED_VALUE"""),"Without Print") -> Without Print | BM13: =IFERROR(__xludf.DUMMYFUNCTION("""COMPUTED_VALUE"""),0) -> 0 | BN13: =IFERROR(__xludf.DUMMYFUNCTION("""COMPUTED_VALUE"""),1926) -> 1926 | BO13: =IFERROR(__xludf.DUMMYFUNCTION("""COMPUTED_VALUE"""),"Repeat Job") -> Repeat Job | BP13: =IFERROR(__xludf.DUMMYFUNCTION("""COMPUTED_VALUE"""),"Leafing") -> Leafing | BQ13: =IFERROR(__xludf.DUMMYFUNCTION("""COMPUTED_VALUE"""),"N/A") -> N/A | BR13: =IFERROR(__xludf.DUMMYFUNCTION("""COMPUTED_VALUE"""),"Normal") -> Normal | BS13: WhiteBack | BT13: Custom | BU13: 300 GSM | BV13: =$BV$9 -> 75 | CD13: =BY13 -> 0 | CE13: =CD13 -> 0
A14: Product Code | B14: Category | C14: Sub Category | D14: Specifications | E14: No. of Ups | F14: Machine | G14: Sheet W | H14: Sheet H | I14: Designing | J14: Gumming Per Sheet | K14: Leafing / Embossing | L14: Window | M14: Pasting | N14: Double Charges | O14: Price Per Sheet | AJ14: Product Code | AK14: Category | AL14: Sub Category | AM14: Specifications | AN14: No. of Ups | AO14: Machine | AP14: Sheet W | AQ14: Sheet H | AR14: Designing | AS14: Gumming Per Sheet | AT14: Leafing / Embossing | AU14: Window | AV14: Pasting | AW14: Double Charges | AX14: Price Per Sheet | BB14: Print | BC14: =IFERROR(__xludf.DUMMYFUNCTION("""COMPUTED_VALUE"""),"Packaging") -> Packaging | BD14: =IFERROR(__xludf.DUMMYFUNCTION("""COMPUTED_VALUE"""),"BO") -> BO | BG14: =IFERROR(__xludf.DUMMYFUNCTION("""COMPUTED_VALUE"""),"Offset") -> Offset | BH14: =IFERROR(__xludf.DUMMYFUNCTION("""COMPUTED_VALUE"""),"Packaging") -> Packaging | BI14: =IFERROR(__xludf.DUMMYFUNCTION("""COMPUTED_VALUE"""),"Other Type") -> Other Type | BJ14: =IFERROR(__xludf.DUMMYFUNCTION("""COMPUTED_VALUE"""),"Plain") -> Plain | BK14: =IFERROR(__xludf.DUMMYFUNCTION("""COMPUTED_VALUE"""),"Plain") -> Plain | BL14: =IFERROR(__xludf.DUMMYFUNCTION("""COMPUTED_VALUE"""),"Without Print") -> Without Print | BM14: =IFERROR(__xludf.DUMMYFUNCTION("""COMPUTED_VALUE"""),0) -> 0 | BN14: =IFERROR(__xludf.DUMMYFUNCTION("""COMPUTED_VALUE"""),1926) -> 1926 | BP14: =IFERROR(__xludf.DUMMYFUNCTION("""COMPUTED_VALUE"""),"Leafing") -> Leafing | BQ14: =IFERROR(__xludf.DUMMYFUNCTION("""COMPUTED_VALUE"""),"N/A") -> N/A | BR14: =IFERROR(__xludf.DUMMYFUNCTION("""COMPUTED_VALUE"""),"Normal") -> Normal | BS14: WhiteBack | BT14: Custom | BU14: 330 GSM | BV14: =$BV$9 -> 75 | CD14: =BY14 -> 0 | CE14: =CD14 -> 0
B15: All | C15: =B10 -> Wrap | D15: Custom Size | E15: =Product6!E2 -> 0 | F15: =Product6!F2 -> 0 | G15: =Product6!W16 -> 0 | H15: =Product6!X16 -> 0 | I15: 100 | N15: 1 | O15: =Product6!Y16 -> 0 | AJ15: =IFERROR(__xludf.DUMMYFUNCTION("ifna(QUERY(A15:O2457,$I$11))"),"") | AK15: =IFERROR(__xludf.DUMMYFUNCTION("""COMPUTED_VALUE"""),"All") -> All | AL15: =IFERROR(__xludf.DUMMYFUNCTION("""COMPUTED_VALUE"""),"Wrap") -> Wrap | AM15: =IFERROR(__xludf.DUMMYFUNCTION("""COMPUTED_VALUE"""),"Custom Size") -> Custom Size | AN15: =IFERROR(__xludf.DUMMYFUNCTION("""COMPUTED_VALUE"""),"") | AO15: =IFERROR(__xludf.DUMMYFUNCTION("""COMPUTED_VALUE"""),"") | AP15: =IFERROR(__xludf.DUMMYFUNCTION("""COMPUTED_VALUE"""),"") | AQ15: =IFERROR(__xludf.DUMMYFUNCTION("""COMPUTED_VALUE"""),"") | AR15: =IFERROR(__xludf.DUMMYFUNCTION("""COMPUTED_VALUE"""),"100") -> 100 | AS15: =IFERROR(__xludf.DUMMYFUNCTION("""COMPUTED_VALUE"""),"") | AT15: =IFERROR(__xludf.DUMMYFUNCTION("""COMPUTED_VALUE"""),"") | AU15: =IFERROR(__xludf.DUMMYFUNCTION("""COMPUTED_VALUE"""),"") | AV15: =IFERROR(__xludf.DUMMYFUNCTION("""COMPUTED_VALUE"""),"") | AW15: =IFERROR(__xludf.DUMMYFUNCTION("""COMPUTED_VALUE"""),"1") -> 1 | AX15: =IFERROR(__xludf.DUMMYFUNCTION("""COMPUTED_VALUE"""),"") | BB15: {=INDEX(#REF!,MATCH(Quotation!B33,#REF!,FALSE),1)} -> #REF! | BC15: =IFERROR(__xludf.DUMMYFUNCTION("""COMPUTED_VALUE"""),"Packaging") -> Packaging | BD15: =IFERROR(__xludf.DUMMYFUNCTION("""COMPUTED_VALUE"""),"Boult") -> Boult | BS15: WhiteBack | BT15: Custom | BU15: 350 GSM | BV15: =$BV$9 -> 75 | CD15: =BY15 -> 0 | CE15: =CD15 -> 0
A16: =IFERROR(__xludf.DUMMYFUNCTION("QUERY(ALLDATA!$A2:$Q2457,$F$12)"),"https://drive.google.com/open?id=1RCVTOA7UAiI06kh64ajGkxHXq7kK4A7v&authuser=jay.agg%40gmail.com&usp=drive_fs") -> https://drive.google.com/open?id=1RCVTOA7UAiI06kh64ajGkxHXq7kK4A7v&authuser=jay.agg%40gmail.com&usp=drive_fs | B16: =IFERROR(__xludf.DUMMYFUNCTION("""COMPUTED_VALUE"""),"Food") -> Food | C16: =IFERROR(__xludf.DUMMYFUNCTION("""COMPUTED_VALUE"""),"Wrap") -> Wrap | D16: =IFERROR(__xludf.DUMMYFUNCTION("""COMPUTED_VALUE"""),"15*74*217 mm") -> 15*74*217 mm | E16: =IFERROR(__xludf.DUMMYFUNCTION("""COMPUTED_VALUE"""),4) -> 4 | F16: =IFERROR(__xludf.DUMMYFUNCTION("""COMPUTED_VALUE"""),1926) -> 1926 | G16: =IFERROR(__xludf.DUMMYFUNCTION("""COMPUTED_VALUE"""),18) -> 18 | H16: =IFERROR(__xludf.DUMMYFUNCTION("""COMPUTED_VALUE"""),23) -> 23 | I16: =IFERROR(__xludf.DUMMYFUNCTION("""COMPUTED_VALUE"""),100) -> 100 | M16: =IFERROR(__xludf.DUMMYFUNCTION("""COMPUTED_VALUE"""),0.1) -> 0.1 | N16: =IFERROR(__xludf.DUMMYFUNCTION("""COMPUTED_VALUE"""),1) -> 1 | P16: =IFERROR(__xludf.DUMMYFUNCTION("""COMPUTED_VALUE"""),"Offset") -> Offset | Q16: =IFERROR(__xludf.DUMMYFUNCTION("""COMPUTED_VALUE"""),"Packaging") -> Packaging | AJ16: =IFERROR(__xludf.DUMMYFUNCTION("""COMPUTED_VALUE"""),"https://drive.google.com/open?id=1RCVTOA7UAiI06kh64ajGkxHXq7kK4A7v&authuser=jay.agg%40gmail.com&usp=drive_fs") -> https://drive.google.com/open?id=1RCVTOA7UAiI06kh64ajGkxHXq7kK4A7v&authuser=jay.agg%40gmail.com&usp=drive_fs | AK16: =IFERROR(__xludf.DUMMYFUNCTION("""COMPUTED_VALUE"""),"Food") -> Food | AL16: =IFERROR(__xludf.DUMMYFUNCTION("""COMPUTED_VALUE"""),"Wrap") -> Wrap | AM16: =IFERROR(__xludf.DUMMYFUNCTION("""COMPUTED_VALUE"""),"15*74*217 mm") -> 15*74*217 mm | AN16: =IFERROR(__xludf.DUMMYFUNCTION("""COMPUTED_VALUE"""),4) -> 4 | AO16: =IFERROR(__xludf.DUMMYFUNCTION("""COMPUTED_VALUE"""),1926) -> 1926 | AP16: =IFERROR(__xludf.DUMMYFUNCTION("""COMPUTED_VALUE"""),18) -> 18 | AQ16: =IFERROR(__xludf.DUMMYFUNCTION("""COMPUTED_VALUE"""),23) -> 23 | AR16: =IFERROR(__xludf.DUMMYFUNCTION("""COMPUTED_VALUE"""),100) -> 100 | AV16: =IFERROR(__xludf.DUMMYFUNCTION("""COMPUTED_VALUE"""),0.1) -> 0.1 | AW16: =IFERROR(__xludf.DUMMYFUNCTION("""COMPUTED_VALUE"""),1) -> 1 | BC16: =IFERROR(__xludf.DUMMYFUNCTION("""COMPUTED_VALUE"""),"Packaging") -> Packaging | BD16: =IFERROR(__xludf.DUMMYFUNCTION("""COMPUTED_VALUE"""),"Camera") -> Camera | BS16: GreyBack | BT16: Khanna | BU16: 230 GSM | BV16: =#REF! -> #REF! | CD16: =BY16 -> 0 | CE16: =CD16 -> 0
A17: =IFERROR(__xludf.DUMMYFUNCTION("""COMPUTED_VALUE"""),"https://drive.google.com/open?id=1RFhjQczaMAqJxxKHOOgWIUcetju9JHbB&authuser=jay.agg%40gmail.com&usp=drive_fs") -> https://drive.google.com/open?id=1RFhjQczaMAqJxxKHOOgWIUcetju9JHbB&authuser=jay.agg%40gmail.com&usp=drive_fs | B17: =IFERROR(__xludf.DUMMYFUNCTION("""COMPUTED_VALUE"""),"Food") -> Food | C17: =IFERROR(__xludf.DUMMYFUNCTION("""COMPUTED_VALUE"""),"Amla Candy") -> Amla Candy | D17: =IFERROR(__xludf.DUMMYFUNCTION("""COMPUTED_VALUE"""),"2.5*4.2*4.9 inch LB") -> 2.5*4.2*4.9 inch LB | E17: =IFERROR(__xludf.DUMMYFUNCTION("""COMPUTED_VALUE"""),4) -> 4 | F17: =IFERROR(__xludf.DUMMYFUNCTION("""COMPUTED_VALUE"""),2029) -> 2029 | G17: =IFERROR(__xludf.DUMMYFUNCTION("""COMPUTED_VALUE"""),20) -> 20 | H17: =IFERROR(__xludf.DUMMYFUNCTION("""COMPUTED_VALUE"""),28) -> 28 | I17: =IFERROR(__xludf.DUMMYFUNCTION("""COMPUTED_VALUE"""),100) -> 100 | M17: =IFERROR(__xludf.DUMMYFUNCTION("""COMPUTED_VALUE"""),0.16) -> 0.16 | N17: =IFERROR(__xludf.DUMMYFUNCTION("""COMPUTED_VALUE"""),1) -> 1 | P17: =IFERROR(__xludf.DUMMYFUNCTION("""COMPUTED_VALUE"""),"Offset") -> Offset | Q17: =IFERROR(__xludf.DUMMYFUNCTION("""COMPUTED_VALUE"""),"Packaging") -> Packaging | AJ17: =IFERROR(__xludf.DUMMYFUNCTION("""COMPUTED_VALUE"""),"https://drive.google.com/open?id=1S0JoeVa-x8xAselnMXu64Vmh1ngS_Cud&authuser=jay.agg%40gmail.com&usp=drive_fs") -> https://drive.google.com/open?id=1S0JoeVa-x8xAselnMXu64Vmh1ngS_Cud&authuser=jay.agg%40gmail.com&usp=drive_fs | AK17: =IFERROR(__xludf.DUMMYFUNCTION("""COMPUTED_VALUE"""),"Food") -> Food | AL17: =IFERROR(__xludf.DUMMYFUNCTION("""COMPUTED_VALUE"""),"Wrap") -> Wrap | AM17: =IFERROR(__xludf.DUMMYFUNCTION("""COMPUTED_VALUE"""),"97*255 mm | 3.8*10 inch") -> 97*255 mm | 3.8*10 inch | AN17: =IFERROR(__xludf.DUMMYFUNCTION("""COMPUTED_VALUE"""),4) -> 4 | AO17: =IFERROR(__xludf.DUMMYFUNCTION("""COMPUTED_VALUE"""),2029) -> 2029 | AP17: =IFERROR(__xludf.DUMMYFUNCTION("""COMPUTED_VALUE"""),18) -> 18 | AQ17: =IFERROR(__xludf.DUMMYFUNCTION("""COMPUTED_VALUE"""),25) -> 25 | AR17: =IFERROR(__xludf.DUMMYFUNCTION("""COMPUTED_VALUE"""),100) -> 100 | AV17: =IFERROR(__xludf.DUMMYFUNCTION("""COMPUTED_VALUE"""),0.12) -> 0.12 | AW17: =IFERROR(__xludf.DUMMYFUNCTION("""COMPUTED_VALUE"""),1) -> 1 | BC17: =IFERROR(__xludf.DUMMYFUNCTION("""COMPUTED_VALUE"""),"Packaging") -> Packaging | BD17: =IFERROR(__xludf.DUMMYFUNCTION("""COMPUTED_VALUE"""),"Candle") -> Candle | BS17: GreyBack | BT17: Sinar Mas | BU17: 250 GSM | BV17: =#REF! -> #REF! | CD17: =BY17 -> 0 | CE17: =CD17 -> 0
A18: =IFERROR(__xludf.DUMMYFUNCTION("""COMPUTED_VALUE"""),"https://drive.google.com/open?id=1R-6x1155ykPUIHal2qHhsGUOhJ93l5nv&authuser=jay.agg%40gmail.com&usp=drive_fs") -> https://drive.google.com/open?id=1R-6x1155ykPUIHal2qHhsGUOhJ93l5nv&authuser=jay.agg%40gmail.com&usp=drive_fs | B18: =IFERROR(__xludf.DUMMYFUNCTION("""COMPUTED_VALUE"""),"Food") -> Food | C18: =IFERROR(__xludf.DUMMYFUNCTION("""COMPUTED_VALUE"""),"Dry Fruit") -> Dry Fruit | D18: =IFERROR(__xludf.DUMMYFUNCTION("""COMPUTED_VALUE"""),"125*65*225 mm") -> 125*65*225 mm | E18: =IFERROR(__xludf.DUMMYFUNCTION("""COMPUTED_VALUE"""),2) -> 2 | F18: =IFERROR(__xludf.DUMMYFUNCTION("""COMPUTED_VALUE"""),1926) -> 1926 | G18: =IFERROR(__xludf.DUMMYFUNCTION("""COMPUTED_VALUE"""),18) -> 18 | H18: =IFERROR(__xludf.DUMMYFUNCTION("""COMPUTED_VALUE"""),24) -> 24 | I18: =IFERROR(__xludf.DUMMYFUNCTION("""COMPUTED_VALUE"""),100) -> 100 | M18: =IFERROR(__xludf.DUMMYFUNCTION("""COMPUTED_VALUE"""),0.16) -> 0.16 | N18: =IFERROR(__xludf.DUMMYFUNCTION("""COMPUTED_VALUE"""),1) -> 1 | P18: =IFERROR(__xludf.DUMMYFUNCTION("""COMPUTED_VALUE"""),"Offset") -> Offset | Q18: =IFERROR(__xludf.DUMMYFUNCTION("""COMPUTED_VALUE"""),"Packaging") -> Packaging | BC18: =IFERROR(__xludf.DUMMYFUNCTION("""COMPUTED_VALUE"""),"Packaging") -> Packaging | BD18: =IFERROR(__xludf.DUMMYFUNCTION("""COMPUTED_VALUE"""),"Carry Bag") -> Carry Bag | BS18: GreyBack | BT18: Normal | BU18: 280 GSM | BV18: =#REF! -> #REF! | CD18: =BY18 -> 0 | CE18: =CD18 -> 0
A19: =IFERROR(__xludf.DUMMYFUNCTION("""COMPUTED_VALUE"""),"https://drive.google.com/open?id=1QvJB9MhtDcXsNtKIflALdqXkVyq8VOgJ&authuser=jay.agg%40gmail.com&usp=drive_fs") -> https://drive.google.com/open?id=1QvJB9MhtDcXsNtKIflALdqXkVyq8VOgJ&authuser=jay.agg%40gmail.com&usp=drive_fs | B19: =IFERROR(__xludf.DUMMYFUNCTION("""COMPUTED_VALUE"""),"Food") -> Food | C19: =IFERROR(__xludf.DUMMYFUNCTION("""COMPUTED_VALUE"""),"Dry Fruit") -> Dry Fruit | D19: =IFERROR(__xludf.DUMMYFUNCTION("""COMPUTED_VALUE"""),"102*38*152 | 4*6*1.5 inch LB") -> 102*38*152 | 4*6*1.5 inch LB | E19: =IFERROR(__xludf.DUMMYFUNCTION("""COMPUTED_VALUE"""),4) -> 4 | F19: =IFERROR(__xludf.DUMMYFUNCTION("""COMPUTED_VALUE"""),1926) -> 1926 | G19: =IFERROR(__xludf.DUMMYFUNCTION("""COMPUTED_VALUE"""),18) -> 18 | H19: =IFERROR(__xludf.DUMMYFUNCTION("""COMPUTED_VALUE"""),23) -> 23 | I19: =IFERROR(__xludf.DUMMYFUNCTION("""COMPUTED_VALUE"""),100) -> 100 | M19: =IFERROR(__xludf.DUMMYFUNCTION("""COMPUTED_VALUE"""),0.16) -> 0.16 | N19: =IFERROR(__xludf.DUMMYFUNCTION("""COMPUTED_VALUE"""),1) -> 1 | P19: =IFERROR(__xludf.DUMMYFUNCTION("""COMPUTED_VALUE"""),"Offset") -> Offset | Q19: =IFERROR(__xludf.DUMMYFUNCTION("""COMPUTED_VALUE"""),"Packaging") -> Packaging | BC19: =IFERROR(__xludf.DUMMYFUNCTION("""COMPUTED_VALUE"""),"Packaging") -> Packaging | BD19: =IFERROR(__xludf.DUMMYFUNCTION("""COMPUTED_VALUE"""),"Cerene") -> Cerene | BS19: GreyBack | BT19: Custom | BU19: 300 GSM | BV19: =$BV$9 -> 75 | CD19: =BY19 -> 0 | CE19: =CD19 -> 0
A20: =IFERROR(__xludf.DUMMYFUNCTION("""COMPUTED_VALUE"""),"https://drive.google.com/open?id=1Qvbr4-fdTQ4l4YcjYooE-rNrrYyvW8zx&authuser=jay.agg%40gmail.com&usp=drive_fs") -> https://drive.google.com/open?id=1Qvbr4-fdTQ4l4YcjYooE-rNrrYyvW8zx&authuser=jay.agg%40gmail.com&usp=drive_fs | B20: =IFERROR(__xludf.DUMMYFUNCTION("""COMPUTED_VALUE"""),"Food") -> Food | C20: =IFERROR(__xludf.DUMMYFUNCTION("""COMPUTED_VALUE"""),"Dry Fruit") -> Dry Fruit | D20: =IFERROR(__xludf.DUMMYFUNCTION("""COMPUTED_VALUE"""),"127*38*203 mm | 5*8*1.5 inch LB") -> 127*38*203 mm | 5*8*1.5 inch LB | E20: =IFERROR(__xludf.DUMMYFUNCTION("""COMPUTED_VALUE"""),2) -> 2 | F20: =IFERROR(__xludf.DUMMYFUNCTION("""COMPUTED_VALUE"""),1926) -> 1926 | G20: =IFERROR(__xludf.DUMMYFUNCTION("""COMPUTED_VALUE"""),14) -> 14 | H20: =IFERROR(__xludf.DUMMYFUNCTION("""COMPUTED_VALUE"""),22) -> 22 | I20: =IFERROR(__xludf.DUMMYFUNCTION("""COMPUTED_VALUE"""),100) -> 100 | M20: =IFERROR(__xludf.DUMMYFUNCTION("""COMPUTED_VALUE"""),0.16) -> 0.16 | N20: =IFERROR(__xludf.DUMMYFUNCTION("""COMPUTED_VALUE"""),1) -> 1 | P20: =IFERROR(__xludf.DUMMYFUNCTION("""COMPUTED_VALUE"""),"Offset") -> Offset | Q20: =IFERROR(__xludf.DUMMYFUNCTION("""COMPUTED_VALUE"""),"Packaging") -> Packaging | BC20: =IFERROR(__xludf.DUMMYFUNCTION("""COMPUTED_VALUE"""),"Packaging") -> Packaging | BD20: =IFERROR(__xludf.DUMMYFUNCTION("""COMPUTED_VALUE"""),"Computer Accessories") -> Computer Accessories | BS20: GreyBack | BT20: Custom | BU20: 330 GSM | BV20: =$BV$9 -> 75 | CD20: =BY20 -> 0 | CE20: =CD20 -> 0
A21: =IFERROR(__xludf.DUMMYFUNCTION("""COMPUTED_VALUE"""),"https://drive.google.com/open?id=1Qwbp_CBztdhd4Oo6pQJ3VR0q6w7viL0j&authuser=jay.agg%40gmail.com&usp=drive_fs") -> https://drive.google.com/open?id=1Qwbp_CBztdhd4Oo6pQJ3VR0q6w7viL0j&authuser=jay.agg%40gmail.com&usp=drive_fs | B21: =IFERROR(__xludf.DUMMYFUNCTION("""COMPUTED_VALUE"""),"Food") -> Food | C21: =IFERROR(__xludf.DUMMYFUNCTION("""COMPUTED_VALUE"""),"Dry Fruit") -> Dry Fruit | D21: =IFERROR(__xludf.DUMMYFUNCTION("""COMPUTED_VALUE"""),"140*38*216 mm | 5.5*8.5*1.5 inch LB") -> 140*38*216 mm | 5.5*8.5*1.5 inch LB | E21: =IFERROR(__xludf.DUMMYFUNCTION("""COMPUTED_VALUE"""),2) -> 2 | F21: =IFERROR(__xludf.DUMMYFUNCTION("""COMPUTED_VALUE"""),1926) -> 1926 | G21: =IFERROR(__xludf.DUMMYFUNCTION("""COMPUTED_VALUE"""),15) -> 15 | H21: =IFERROR(__xludf.DUMMYFUNCTION("""COMPUTED_VALUE"""),25) -> 25 | I21: =IFERROR(__xludf.DUMMYFUNCTION("""COMPUTED_VALUE"""),100) -> 100 | M21: =IFERROR(__xludf.DUMMYFUNCTION("""COMPUTED_VALUE"""),0.16) -> 0.16 | N21: =IFERROR(__xludf.DUMMYFUNCTION("""COMPUTED_VALUE"""),1) -> 1 | P21: =IFERROR(__xludf.DUMMYFUNCTION("""COMPUTED_VALUE"""),"Offset") -> Offset | Q21: =IFERROR(__xludf.DUMMYFUNCTION("""COMPUTED_VALUE"""),"Packaging") -> Packaging | BC21: =IFERROR(__xludf.DUMMYFUNCTION("""COMPUTED_VALUE"""),"Packaging") -> Packaging | BD21: =IFERROR(__xludf.DUMMYFUNCTION("""COMPUTED_VALUE"""),"Cones") -> Cones | BS21: GreyBack | BT21: Custom | BU21: 350 GSM | BV21: =$BV$9 -> 75 | CD21: =BY21 -> 0 | CE21: =CD21 -> 0
A22: =IFERROR(__xludf.DUMMYFUNCTION("""COMPUTED_VALUE"""),"https://drive.google.com/open?id=1R0wA1QXQbAwYILUJUKO7z4Ci3IcHThXO&authuser=jay.agg%40gmail.com&usp=drive_fs") -> https://drive.google.com/open?id=1R0wA1QXQbAwYILUJUKO7z4Ci3IcHThXO&authuser=jay.agg%40gmail.com&usp=drive_fs | B22: =IFERROR(__xludf.DUMMYFUNCTION("""COMPUTED_VALUE"""),"Food") -> Food | C22: =IFERROR(__xludf.DUMMYFUNCTION("""COMPUTED_VALUE"""),"Dry Fruit") -> Dry Fruit | D22: =IFERROR(__xludf.DUMMYFUNCTION("""COMPUTED_VALUE"""),"100gram 4*1.5*5 inch LB") -> 100gram 4*1.5*5 inch LB | E22: =IFERROR(__xludf.DUMMYFUNCTION("""COMPUTED_VALUE"""),4) -> 4 | F22: =IFERROR(__xludf.DUMMYFUNCTION("""COMPUTED_VALUE"""),1926) -> 1926 | G22: =IFERROR(__xludf.DUMMYFUNCTION("""COMPUTED_VALUE"""),15) -> 15 | H22: =IFERROR(__xludf.DUMMYFUNCTION("""COMPUTED_VALUE"""),25) -> 25 | I22: =IFERROR(__xludf.DUMMYFUNCTION("""COMPUTED_VALUE"""),100) -> 100 | L22: =IFERROR(__xludf.DUMMYFUNCTION("""COMPUTED_VALUE"""),1) -> 1 | M22: =IFERROR(__xludf.DUMMYFUNCTION("""COMPUTED_VALUE"""),0.16) -> 0.16 | N22: =IFERROR(__xludf.DUMMYFUNCTION("""COMPUTED_VALUE"""),1) -> 1 | P22: =IFERROR(__xludf.DUMMYFUNCTION("""COMPUTED_VALUE"""),"Offset") -> Offset | Q22: =IFERROR(__xludf.DUMMYFUNCTION("""COMPUTED_VALUE"""),"Packaging") -> Packaging | BC22: =IFERROR(__xludf.DUMMYFUNCTION("""COMPUTED_VALUE"""),"Packaging") -> Packaging | BD22: =IFERROR(__xludf.DUMMYFUNCTION("""COMPUTED_VALUE"""),"Corrugation") -> Corrugation | BS22: Maplitho | BT22: Normal | BU22: 65 GSM | BV22: =#REF! -> #REF! | CD22: =BY22 -> 0 | CE22: =CD22 -> 0
A23: =IFERROR(__xludf.DUMMYFUNCTION("""COMPUTED_VALUE"""),"https://drive.google.com/open?id=1R61V6cd_s3Pq01sfSW5K3t7WSGP_L0As&authuser=jay.agg%40gmail.com&usp=drive_fs") -> https://drive.google.com/open?id=1R61V6cd_s3Pq01sfSW5K3t7WSGP_L0As&authuser=jay.agg%40gmail.com&usp=drive_fs | B23: =IFERROR(__xludf.DUMMYFUNCTION("""COMPUTED_VALUE"""),"Food") -> Food | C23: =IFERROR(__xludf.DUMMYFUNCTION("""COMPUTED_VALUE"""),"Dry Fruit") -> Dry Fruit | D23: =IFERROR(__xludf.DUMMYFUNCTION("""COMPUTED_VALUE"""),"200gram 4.5*1.5*7 inch LB") -> 200gram 4.5*1.5*7 inch LB | E23: =IFERROR(__xludf.DUMMYFUNCTION("""COMPUTED_VALUE"""),4) -> 4 | F23: =IFERROR(__xludf.DUMMYFUNCTION("""COMPUTED_VALUE"""),1926) -> 1926 | G23: =IFERROR(__xludf.DUMMYFUNCTION("""COMPUTED_VALUE"""),19) -> 19 | H23: =IFERROR(__xludf.DUMMYFUNCTION("""COMPUTED_VALUE"""),26) -> 26 | I23: =IFERROR(__xludf.DUMMYFUNCTION("""COMPUTED_VALUE"""),100) -> 100 | L23: =IFERROR(__xludf.DUMMYFUNCTION("""COMPUTED_VALUE"""),1) -> 1 | M23: =IFERROR(__xludf.DUMMYFUNCTION("""COMPUTED_VALUE"""),0.16) -> 0.16 | N23: =IFERROR(__xludf.DUMMYFUNCTION("""COMPUTED_VALUE"""),1) -> 1 | P23: =IFERROR(__xludf.DUMMYFUNCTION("""COMPUTED_VALUE"""),"Offset") -> Offset | Q23: =IFERROR(__xludf.DUMMYFUNCTION("""COMPUTED_VALUE"""),"Packaging") -> Packaging | BC23: =IFERROR(__xludf.DUMMYFUNCTION("""COMPUTED_VALUE"""),"Packaging") -> Packaging | BD23: =IFERROR(__xludf.DUMMYFUNCTION("""COMPUTED_VALUE"""),"Cosmetic") -> Cosmetic | BS23: Maplitho | BT23: Custom | BU23: 80 GSM | BV23: =Quotation!$C$21 -> 0 | CD23: =BY23 -> 0 | CE23: =CD23 -> 0
A24: =IFERROR(__xludf.DUMMYFUNCTION("""COMPUTED_VALUE"""),"https://drive.google.com/open?id=1R69JTM091j0R6Hbk7JlIcmy1o0TJXQlC&authuser=jay.agg%40gmail.com&usp=drive_fs") -> https://drive.google.com/open?id=1R69JTM091j0R6Hbk7JlIcmy1o0TJXQlC&authuser=jay.agg%40gmail.com&usp=drive_fs | B24: =IFERROR(__xludf.DUMMYFUNCTION("""COMPUTED_VALUE"""),"Food") -> Food | C24: =IFERROR(__xludf.DUMMYFUNCTION("""COMPUTED_VALUE"""),"Dry Fruit") -> Dry Fruit | D24: =IFERROR(__xludf.DUMMYFUNCTION("""COMPUTED_VALUE"""),"250gram 5*1.5*7 inch LB") -> 250gram 5*1.5*7 inch LB | E24: =IFERROR(__xludf.DUMMYFUNCTION("""COMPUTED_VALUE"""),2) -> 2 | F24: =IFERROR(__xludf.DUMMYFUNCTION("""COMPUTED_VALUE"""),1926) -> 1926 | G24: =IFERROR(__xludf.DUMMYFUNCTION("""COMPUTED_VALUE"""),14) -> 14 | H24: =IFERROR(__xludf.DUMMYFUNCTION("""COMPUTED_VALUE"""),19) -> 19 | I24: =IFERROR(__xludf.DUMMYFUNCTION("""COMPUTED_VALUE"""),100) -> 100 | L24: =IFERROR(__xludf.DUMMYFUNCTION("""COMPUTED_VALUE"""),1) -> 1 | M24: =IFERROR(__xludf.DUMMYFUNCTION("""COMPUTED_VALUE"""),0.16) -> 0.16 | N24: =IFERROR(__xludf.DUMMYFUNCTION("""COMPUTED_VALUE"""),1) -> 1 | P24: =IFERROR(__xludf.DUMMYFUNCTION("""COMPUTED_VALUE"""),"Offset") -> Offset | Q24: =IFERROR(__xludf.DUMMYFUNCTION("""COMPUTED_VALUE"""),"Packaging") -> Packaging | BC24: =IFERROR(__xludf.DUMMYFUNCTION("""COMPUTED_VALUE"""),"Packaging") -> Packaging | BD24: =IFERROR(__xludf.DUMMYFUNCTION("""COMPUTED_VALUE"""),"Cup") -> Cup | BS24: Maplitho | BT24: Normal | BU24: 90 GSM | BV24: =$BV$22 -> #REF! | CD24: =BY24 -> 0 | CE24: =CD24 -> 0
A25: =IFERROR(__xludf.DUMMYFUNCTION("""COMPUTED_VALUE"""),"https://drive.google.com/open?id=1QTWTuFZk9eNr_4lY0kX3TKgeYtsriRPs&authuser=jay.agg%40gmail.com&usp=drive_fs") -> https://drive.google.com/open?id=1QTWTuFZk9eNr_4lY0kX3TKgeYtsriRPs&authuser=jay.agg%40gmail.com&usp=drive_fs | B25: =IFERROR(__xludf.DUMMYFUNCTION("""COMPUTED_VALUE"""),"Food") -> Food | C25: =IFERROR(__xludf.DUMMYFUNCTION("""COMPUTED_VALUE"""),"Fast Food") -> Fast Food | D25: =IFERROR(__xludf.DUMMYFUNCTION("""COMPUTED_VALUE"""),"8*7*2 inch") -> 8*7*2 inch | E25: =IFERROR(__xludf.DUMMYFUNCTION("""COMPUTED_VALUE"""),1) -> 1 | F25: =IFERROR(__xludf.DUMMYFUNCTION("""COMPUTED_VALUE"""),1926) -> 1926 | G25: =IFERROR(__xludf.DUMMYFUNCTION("""COMPUTED_VALUE"""),18) -> 18 | H25: =IFERROR(__xludf.DUMMYFUNCTION("""COMPUTED_VALUE"""),19) -> 19 | I25: =IFERROR(__xludf.DUMMYFUNCTION("""COMPUTED_VALUE"""),100) -> 100 | N25: =IFERROR(__xludf.DUMMYFUNCTION("""COMPUTED_VALUE"""),1) -> 1 | P25: =IFERROR(__xludf.DUMMYFUNCTION("""COMPUTED_VALUE"""),"Offset") -> Offset | Q25: =IFERROR(__xludf.DUMMYFUNCTION("""COMPUTED_VALUE"""),"Packaging") -> Packaging | BC25: =IFERROR(__xludf.DUMMYFUNCTION("""COMPUTED_VALUE"""),"Packaging") -> Packaging | BD25: =IFERROR(__xludf.DUMMYFUNCTION("""COMPUTED_VALUE"""),"Daily Essential") -> Daily Essential | BS25: Maplitho | BT25: Normal | BU25: 100 GSM | BV25: =$BV$22 -> #REF! | CD25: =BY25 -> 0 | CE25: =CD25 -> 0
A26: =IFERROR(__xludf.DUMMYFUNCTION("""COMPUTED_VALUE"""),"https://drive.google.com/open?id=1QhZ36zVV0AY4GNL7jcG9woN0_jfH4vH2&authuser=jay.agg%40gmail.com&usp=drive_fs") -> https://drive.google.com/open?id=1QhZ36zVV0AY4GNL7jcG9woN0_jfH4vH2&authuser=jay.agg%40gmail.com&usp=drive_fs | B26: =IFERROR(__xludf.DUMMYFUNCTION("""COMPUTED_VALUE"""),"Food") -> Food | C26: =IFERROR(__xludf.DUMMYFUNCTION("""COMPUTED_VALUE"""),"Fast Food") -> Fast Food | D26: =IFERROR(__xludf.DUMMYFUNCTION("""COMPUTED_VALUE"""),"5*5*4.5 inch") -> 5*5*4.5 inch | E26: =IFERROR(__xludf.DUMMYFUNCTION("""COMPUTED_VALUE"""),2) -> 2 | F26: =IFERROR(__xludf.DUMMYFUNCTION("""COMPUTED_VALUE"""),1926) -> 1926 | G26: =IFERROR(__xludf.DUMMYFUNCTION("""COMPUTED_VALUE"""),19.5) -> 19.5 | H26: =IFERROR(__xludf.DUMMYFUNCTION("""COMPUTED_VALUE"""),23) -> 23 | I26: =IFERROR(__xludf.DUMMYFUNCTION("""COMPUTED_VALUE"""),100) -> 100 | N26: =IFERROR(__xludf.DUMMYFUNCTION("""COMPUTED_VALUE"""),1) -> 1 | P26: =IFERROR(__xludf.DUMMYFUNCTION("""COMPUTED_VALUE"""),"Offset") -> Offset | Q26: =IFERROR(__xludf.DUMMYFUNCTION("""COMPUTED_VALUE"""),"Packaging") -> Packaging | BC26: =IFERROR(__xludf.DUMMYFUNCTION("""COMPUTED_VALUE"""),"Packaging") -> Packaging | BD26: =IFERROR(__xludf.DUMMYFUNCTION("""COMPUTED_VALUE"""),"Dhoop") -> Dhoop | BS26: Maplitho | BT26: Normal | BU26: 110 GSM | BV26: =$BV$22 -> #REF! | CD26: =BY26 -> 0 | CE26: =CD26 -> 0
A27: =IFERROR(__xludf.DUMMYFUNCTION("""COMPUTED_VALUE"""),"https://drive.google.com/open?id=1Qhw5hCt6AslPxvpSURfZvOXwooNNK0lB&authuser=jay.agg%40gmail.com&usp=drive_fs") -> https://drive.google.com/open?id=1Qhw5hCt6AslPxvpSURfZvOXwooNNK0lB&authuser=jay.agg%40gmail.com&usp=drive_fs | B27: =IFERROR(__xludf.DUMMYFUNCTION("""COMPUTED_VALUE"""),"Food") -> Food | C27: =IFERROR(__xludf.DUMMYFUNCTION("""COMPUTED_VALUE"""),"Fast Food") -> Fast Food | D27: =IFERROR(__xludf.DUMMYFUNCTION("""COMPUTED_VALUE"""),"100*150*45 mm") -> 100*150*45 mm | E27: =IFERROR(__xludf.DUMMYFUNCTION("""COMPUTED_VALUE"""),2) -> 2 | F27: =IFERROR(__xludf.DUMMYFUNCTION("""COMPUTED_VALUE"""),1926) -> 1926 | G27: =IFERROR(__xludf.DUMMYFUNCTION("""COMPUTED_VALUE"""),15) -> 15 | H27: =IFERROR(__xludf.DUMMYFUNCTION("""COMPUTED_VALUE"""),20) -> 20 | I27: =IFERROR(__xludf.DUMMYFUNCTION("""COMPUTED_VALUE"""),100) -> 100 | N27: =IFERROR(__xludf.DUMMYFUNCTION("""COMPUTED_VALUE"""),1) -> 1 | P27: =IFERROR(__xludf.DUMMYFUNCTION("""COMPUTED_VALUE"""),"Offset") -> Offset | Q27: =IFERROR(__xludf.DUMMYFUNCTION("""COMPUTED_VALUE"""),"Packaging") -> Packaging | BC27: =IFERROR(__xludf.DUMMYFUNCTION("""COMPUTED_VALUE"""),"Packaging") -> Packaging | BD27: =IFERROR(__xludf.DUMMYFUNCTION("""COMPUTED_VALUE"""),"Dude Love") -> Dude Love | BS27: Maplitho | BT27: Normal | BU27: 130 GSM | BV27: =$BV$22 -> #REF! | CD27: =BY27 -> 0 | CE27: =CD27 -> 0
A28: =IFERROR(__xludf.DUMMYFUNCTION("""COMPUTED_VALUE"""),"https://drive.google.com/open?id=1QUlYw3yWCJ5eG6Uy83i49XImWyIv8ly_&authuser=jay.agg%40gmail.com&usp=drive_fs") -> https://drive.google.com/open?id=1QUlYw3yWCJ5eG6Uy83i49XImWyIv8ly_&authuser=jay.agg%40gmail.com&usp=drive_fs | B28: =IFERROR(__xludf.DUMMYFUNCTION("""COMPUTED_VALUE"""),"Food") -> Food | C28: =IFERROR(__xludf.DUMMYFUNCTION("""COMPUTED_VALUE"""),"Khakra") -> Khakra | D28: =IFERROR(__xludf.DUMMYFUNCTION("""COMPUTED_VALUE"""),"220*220*30 mm") -> 220*220*30 mm | E28: =IFERROR(__xludf.DUMMYFUNCTION("""COMPUTED_VALUE"""),1) -> 1 | F28: =IFERROR(__xludf.DUMMYFUNCTION("""COMPUTED_VALUE"""),1926) -> 1926 | G28: =IFERROR(__xludf.DUMMYFUNCTION("""COMPUTED_VALUE"""),13) -> 13 | H28: =IFERROR(__xludf.DUMMYFUNCTION("""COMPUTED_VALUE"""),21) -> 21 | I28: =IFERROR(__xludf.DUMMYFUNCTION("""COMPUTED_VALUE"""),100) -> 100 | M28: =IFERROR(__xludf.DUMMYFUNCTION("""COMPUTED_VALUE"""),0.1) -> 0.1 | N28: =IFERROR(__xludf.DUMMYFUNCTION("""COMPUTED_VALUE"""),1) -> 1 | P28: =IFERROR(__xludf.DUMMYFUNCTION("""COMPUTED_VALUE"""),"Offset") -> Offset | Q28: =IFERROR(__xludf.DUMMYFUNCTION("""COMPUTED_VALUE"""),"Packaging") -> Packaging | BC28: =IFERROR(__xludf.DUMMYFUNCTION("""COMPUTED_VALUE"""),"Packaging") -> Packaging | BD28: =IFERROR(__xludf.DUMMYFUNCTION("""COMPUTED_VALUE"""),"Electricity") -> Electricity | BS28: Maplitho | BT28: Normal | BU28: 150 GSM | BV28: =$BV$22 -> #REF! | CD28: =BY28 -> 0 | CE28: =CD28 -> 0
A29: =IFERROR(__xludf.DUMMYFUNCTION("""COMPUTED_VALUE"""),"https://drive.google.com/open?id=1QRiCFXEjTTmENEZKNbx8VjC2NioVX2p8&authuser=jay.agg%40gmail.com&usp=drive_fs") -> https://drive.google.com/open?id=1QRiCFXEjTTmENEZKNbx8VjC2NioVX2p8&authuser=jay.agg%40gmail.com&usp=drive_fs | B29: =IFERROR(__xludf.DUMMYFUNCTION("""COMPUTED_VALUE"""),"Food") -> Food | C29: =IFERROR(__xludf.DUMMYFUNCTION("""COMPUTED_VALUE"""),"Walnut") -> Walnut | D29: =IFERROR(__xludf.DUMMYFUNCTION("""COMPUTED_VALUE"""),"24*46*161 mm") -> 24*46*161 mm | E29: =IFERROR(__xludf.DUMMYFUNCTION("""COMPUTED_VALUE"""),9) -> 9 | F29: =IFERROR(__xludf.DUMMYFUNCTION("""COMPUTED_VALUE"""),1926) -> 1926 | G29: =IFERROR(__xludf.DUMMYFUNCTION("""COMPUTED_VALUE"""),19) -> 19 | H29: =IFERROR(__xludf.DUMMYFUNCTION("""COMPUTED_VALUE"""),26) -> 26 | I29: =IFERROR(__xludf.DUMMYFUNCTION("""COMPUTED_VALUE"""),100) -> 100 | M29: =IFERROR(__xludf.DUMMYFUNCTION("""COMPUTED_VALUE"""),0.1) -> 0.1 | N29: =IFERROR(__xludf.DUMMYFUNCTION("""COMPUTED_VALUE"""),1) -> 1 | P29: =IFERROR(__xludf.DUMMYFUNCTION("""COMPUTED_VALUE"""),"Offset") -> Offset | Q29: =IFERROR(__xludf.DUMMYFUNCTION("""COMPUTED_VALUE"""),"Packaging") -> Packaging | BC29: =IFERROR(__xludf.DUMMYFUNCTION("""COMPUTED_VALUE"""),"Packaging") -> Packaging | BD29: =IFERROR(__xludf.DUMMYFUNCTION("""COMPUTED_VALUE"""),"Everstylish") -> Everstylish | CD29: =BY29 -> 0 | CE29: =CD29 -> 0
A30: =IFERROR(__xludf.DUMMYFUNCTION("""COMPUTED_VALUE"""),"https://drive.google.com/open?id=1QQdUxmlDOPkf9Hsc7uKFwvH0Xou6f57E&authuser=jay.agg%40gmail.com&usp=drive_fs") -> https://drive.google.com/open?id=1QQdUxmlDOPkf9Hsc7uKFwvH0Xou6f57E&authuser=jay.agg%40gmail.com&usp=drive_fs | B30: =IFERROR(__xludf.DUMMYFUNCTION("""COMPUTED_VALUE"""),"Food") -> Food | C30: =IFERROR(__xludf.DUMMYFUNCTION("""COMPUTED_VALUE"""),"Chocolate") -> Chocolate | D30: =IFERROR(__xludf.DUMMYFUNCTION("""COMPUTED_VALUE"""),"50*50*100 mm") -> 50*50*100 mm | E30: =IFERROR(__xludf.DUMMYFUNCTION("""COMPUTED_VALUE"""),6) -> 6 | F30: =IFERROR(__xludf.DUMMYFUNCTION("""COMPUTED_VALUE"""),1926) -> 1926 | G30: =IFERROR(__xludf.DUMMYFUNCTION("""COMPUTED_VALUE"""),18) -> 18 | H30: =IFERROR(__xludf.DUMMYFUNCTION("""COMPUTED_VALUE"""),25) -> 25 | I30: =IFERROR(__xludf.DUMMYFUNCTION("""COMPUTED_VALUE"""),100) -> 100 | M30: =IFERROR(__xludf.DUMMYFUNCTION("""COMPUTED_VALUE"""),0.1) -> 0.1 | N30: =IFERROR(__xludf.DUMMYFUNCTION("""COMPUTED_VALUE"""),1) -> 1 | P30: =IFERROR(__xludf.DUMMYFUNCTION("""COMPUTED_VALUE"""),"Offset") -> Offset | Q30: =IFERROR(__xludf.DUMMYFUNCTION("""COMPUTED_VALUE"""),"Packaging") -> Packaging | BC30: =IFERROR(__xludf.DUMMYFUNCTION("""COMPUTED_VALUE"""),"Packaging") -> Packaging | BD30: =IFERROR(__xludf.DUMMYFUNCTION("""COMPUTED_VALUE"""),"FMCG") -> FMCG | CD30: =BY30 -> 0 | CE30: =CD30 -> 0
A31: =IFERROR(__xludf.DUMMYFUNCTION("""COMPUTED_VALUE"""),"https://drive.google.com/open?id=1QtXn0evE-9VW4-ZQJmVDufU_5NTVKUY6&authuser=jay.agg%40gmail.com&usp=drive_fs") -> https://drive.google.com/open?id=1QtXn0evE-9VW4-ZQJmVDufU_5NTVKUY6&authuser=jay.agg%40gmail.com&usp=drive_fs | B31: =IFERROR(__xludf.DUMMYFUNCTION("""COMPUTED_VALUE"""),"Food") -> Food | C31: =IFERROR(__xludf.DUMMYFUNCTION("""COMPUTED_VALUE"""),"Butter") -> Butter | D31: =IFERROR(__xludf.DUMMYFUNCTION("""COMPUTED_VALUE"""),"70*63*130 mm") -> 70*63*130 mm | E31: =IFERROR(__xludf.DUMMYFUNCTION("""COMPUTED_VALUE"""),2) -> 2 | F31: =IFERROR(__xludf.DUMMYFUNCTION("""COMPUTED_VALUE"""),1926) -> 1926 | G31: =IFERROR(__xludf.DUMMYFUNCTION("""COMPUTED_VALUE"""),12) -> 12 | H31: =IFERROR(__xludf.DUMMYFUNCTION("""COMPUTED_VALUE"""),21) -> 21 | I31: =IFERROR(__xludf.DUMMYFUNCTION("""COMPUTED_VALUE"""),100) -> 100 | M31: =IFERROR(__xludf.DUMMYFUNCTION("""COMPUTED_VALUE"""),0.1) -> 0.1 | N31: =IFERROR(__xludf.DUMMYFUNCTION("""COMPUTED_VALUE"""),1) -> 1 | P31: =IFERROR(__xludf.DUMMYFUNCTION("""COMPUTED_VALUE"""),"Offset") -> Offset | Q31: =IFERROR(__xludf.DUMMYFUNCTION("""COMPUTED_VALUE"""),"Packaging") -> Packaging | BC31: =IFERROR(__xludf.DUMMYFUNCTION("""COMPUTED_VALUE"""),"Packaging") -> Packaging | BD31: =IFERROR(__xludf.DUMMYFUNCTION("""COMPUTED_VALUE"""),"Food") -> Food | BS31: Art Card | BT31: Normal | BU31: 90 GSM | BV31: =#REF! -> #REF! | CD31: =BY31 -> 0 | CE31: =CD31 -> 0
A32: =IFERROR(__xludf.DUMMYFUNCTION("""COMPUTED_VALUE"""),"https://drive.google.com/open?id=1j2Ak7n2uIi0WIIJrDAWZ9xkRCHIeqUHe&authuser=jay.agg%40gmail.com&usp=drive_fs") -> https://drive.google.com/open?id=1j2Ak7n2uIi0WIIJrDAWZ9xkRCHIeqUHe&authuser=jay.agg%40gmail.com&usp=drive_fs | B32: =IFERROR(__xludf.DUMMYFUNCTION("""COMPUTED_VALUE"""),"Food") -> Food | C32: =IFERROR(__xludf.DUMMYFUNCTION("""COMPUTED_VALUE"""),"Fast Food") -> Fast Food | D32: =IFERROR(__xludf.DUMMYFUNCTION("""COMPUTED_VALUE"""),"Sleeve 5.25*3.25*2.25 inch") -> Sleeve 5.25*3.25*2.25 inch | E32: =IFERROR(__xludf.DUMMYFUNCTION("""COMPUTED_VALUE"""),6) -> 6 | F32: =IFERROR(__xludf.DUMMYFUNCTION("""COMPUTED_VALUE"""),1926) -> 1926 | G32: =IFERROR(__xludf.DUMMYFUNCTION("""COMPUTED_VALUE"""),18) -> 18 | H32: =IFERROR(__xludf.DUMMYFUNCTION("""COMPUTED_VALUE"""),23) -> 23 | I32: =IFERROR(__xludf.DUMMYFUNCTION("""COMPUTED_VALUE"""),100) -> 100 | M32: =IFERROR(__xludf.DUMMYFUNCTION("""COMPUTED_VALUE"""),0.1) -> 0.1 | N32: =IFERROR(__xludf.DUMMYFUNCTION("""COMPUTED_VALUE"""),1) -> 1 | P32: =IFERROR(__xludf.DUMMYFUNCTION("""COMPUTED_VALUE"""),"Offset") -> Offset | Q32: =IFERROR(__xludf.DUMMYFUNCTION("""COMPUTED_VALUE"""),"Packaging") -> Packaging | BC32: =IFERROR(__xludf.DUMMYFUNCTION("""COMPUTED_VALUE"""),"Packaging") -> Packaging | BD32: =IFERROR(__xludf.DUMMYFUNCTION("""COMPUTED_VALUE"""),"Fratelli") -> Fratelli | BS32: Art Card | BT32: Normal | BU32: 100 GSM | BV32: =#REF! -> #REF! | CD32: =BY32 -> 0 | CE32: =CD32 -> 0
A33: =IFERROR(__xludf.DUMMYFUNCTION("""COMPUTED_VALUE"""),"https://drive.google.com/open?id=1jIKxVpMBt0sYXYuHJ9pjoEVFnOlIpxpb&authuser=jay.agg%40gmail.com&usp=drive_fs") -> https://drive.google.com/open?id=1jIKxVpMBt0sYXYuHJ9pjoEVFnOlIpxpb&authuser=jay.agg%40gmail.com&usp=drive_fs | B33: =IFERROR(__xludf.DUMMYFUNCTION("""COMPUTED_VALUE"""),"Food") -> Food | C33: =IFERROR(__xludf.DUMMYFUNCTION("""COMPUTED_VALUE"""),"Fast Food") -> Fast Food | D33: =IFERROR(__xludf.DUMMYFUNCTION("""COMPUTED_VALUE"""),"9.375*3.75*2 inch") -> 9.375*3.75*2 inch | E33: =IFERROR(__xludf.DUMMYFUNCTION("""COMPUTED_VALUE"""),2) -> 2 | F33: =IFERROR(__xludf.DUMMYFUNCTION("""COMPUTED_VALUE"""),1926) -> 1926 | G33: =IFERROR(__xludf.DUMMYFUNCTION("""COMPUTED_VALUE"""),18) -> 18 | H33: =IFERROR(__xludf.DUMMYFUNCTION("""COMPUTED_VALUE"""),25) -> 25 | I33: =IFERROR(__xludf.DUMMYFUNCTION("""COMPUTED_VALUE"""),100) -> 100 | N33: =IFERROR(__xludf.DUMMYFUNCTION("""COMPUTED_VALUE"""),1) -> 1 | P33: =IFERROR(__xludf.DUMMYFUNCTION("""COMPUTED_VALUE"""),"Offset") -> Offset | Q33: =IFERROR(__xludf.DUMMYFUNCTION("""COMPUTED_VALUE"""),"Packaging") -> Packaging | BC33: =IFERROR(__xludf.DUMMYFUNCTION("""COMPUTED_VALUE"""),"Packaging") -> Packaging | BD33: =IFERROR(__xludf.DUMMYFUNCTION("""COMPUTED_VALUE"""),"Games") -> Games | BS33: Art Card | BT33: Normal | BU33: 110 GSM | BV33: =#REF! -> #REF! | CD33: =BY33 -> 0 | CE33: =CD33 -> 0
A34: =IFERROR(__xludf.DUMMYFUNCTION("""COMPUTED_VALUE"""),"https://drive.google.com/open?id=1jPGlPvth33ow0BsuXPn_9Fd0aGa4tOR5&authuser=jay.agg%40gmail.com&usp=drive_fs") -> https://drive.google.com/open?id=1jPGlPvth33ow0BsuXPn_9Fd0aGa4tOR5&authuser=jay.agg%40gmail.com&usp=drive_fs | B34: =IFERROR(__xludf.DUMMYFUNCTION("""COMPUTED_VALUE"""),"Food") -> Food | C34: =IFERROR(__xludf.DUMMYFUNCTION("""COMPUTED_VALUE"""),"Fast Food") -> Fast Food | D34: =IFERROR(__xludf.DUMMYFUNCTION("""COMPUTED_VALUE"""),"Momos 5.25*3.25*2.25 inch") -> Momos 5.25*3.25*2.25 inch | E34: =IFERROR(__xludf.DUMMYFUNCTION("""COMPUTED_VALUE"""),2) -> 2 | F34: =IFERROR(__xludf.DUMMYFUNCTION("""COMPUTED_VALUE"""),1926) -> 1926 | G34: =IFERROR(__xludf.DUMMYFUNCTION("""COMPUTED_VALUE"""),15) -> 15 | H34: =IFERROR(__xludf.DUMMYFUNCTION("""COMPUTED_VALUE"""),25) -> 25 | I34: =IFERROR(__xludf.DUMMYFUNCTION("""COMPUTED_VALUE"""),100) -> 100 | N34: =IFERROR(__xludf.DUMMYFUNCTION("""COMPUTED_VALUE"""),1) -> 1 | P34: =IFERROR(__xludf.DUMMYFUNCTION("""COMPUTED_VALUE"""),"Offset") -> Offset | Q34: =IFERROR(__xludf.DUMMYFUNCTION("""COMPUTED_VALUE"""),"Packaging") -> Packaging | BC34: =IFERROR(__xludf.DUMMYFUNCTION("""COMPUTED_VALUE"""),"Packaging") -> Packaging | BD34: =IFERROR(__xludf.DUMMYFUNCTION("""COMPUTED_VALUE"""),"Gugal Loban Cup") -> Gugal Loban Cup | BS34: Art Card | BT34: Normal | BU34: 130 GSM | BV34: =#REF! -> #REF! | CD34: =BY34 -> 0 | CE34: =CD34 -> 0
A35: =IFERROR(__xludf.DUMMYFUNCTION("""COMPUTED_VALUE"""),"https://drive.google.com/open?id=1jPSj61Xjqqhp0yAUgpJijU3oteatln8h&authuser=jay.agg%40gmail.com&usp=drive_fs") -> https://drive.google.com/open?id=1jPSj61Xjqqhp0yAUgpJijU3oteatln8h&authuser=jay.agg%40gmail.com&usp=drive_fs | B35: =IFERROR(__xludf.DUMMYFUNCTION("""COMPUTED_VALUE"""),"Food") -> Food | C35: =IFERROR(__xludf.DUMMYFUNCTION("""COMPUTED_VALUE"""),"Fast Food") -> Fast Food | D35: =IFERROR(__xludf.DUMMYFUNCTION("""COMPUTED_VALUE"""),"Kathi Roll 55*55*230 mm LB") -> Kathi Roll 55*55*230 mm LB | E35: =IFERROR(__xludf.DUMMYFUNCTION("""COMPUTED_VALUE"""),4) -> 4 | F35: =IFERROR(__xludf.DUMMYFUNCTION("""COMPUTED_VALUE"""),1926) -> 1926 | G35: =IFERROR(__xludf.DUMMYFUNCTION("""COMPUTED_VALUE"""),19) -> 19 | H35: =IFERROR(__xludf.DUMMYFUNCTION("""COMPUTED_VALUE"""),26) -> 26 | I35: =IFERROR(__xludf.DUMMYFUNCTION("""COMPUTED_VALUE"""),100) -> 100 | M35: =IFERROR(__xludf.DUMMYFUNCTION("""COMPUTED_VALUE"""),0.4) -> 0.4 | N35: =IFERROR(__xludf.DUMMYFUNCTION("""COMPUTED_VALUE"""),1) -> 1 | P35: =IFERROR(__xludf.DUMMYFUNCTION("""COMPUTED_VALUE"""),"Offset") -> Offset | Q35: =IFERROR(__xludf.DUMMYFUNCTION("""COMPUTED_VALUE"""),"Packaging") -> Packaging | BC35: =IFERROR(__xludf.DUMMYFUNCTION("""COMPUTED_VALUE"""),"Packaging") -> Packaging | BD35: =IFERROR(__xludf.DUMMYFUNCTION("""COMPUTED_VALUE"""),"Hard Bound") -> Hard Bound | BS35: Art Card | BT35: Normal | BU35: 150 GSM | BV35: =#REF! -> #REF! | CD35: =BY35 -> 0 | CE35: =CD35 -> 0
A36: =IFERROR(__xludf.DUMMYFUNCTION("""COMPUTED_VALUE"""),"https://drive.google.com/open?id=1n4sM_hMizxMor4aS4-NffW1QEWkmmRaC&authuser=jay.agg%40gmail.com&usp=drive_fs") -> https://drive.google.com/open?id=1n4sM_hMizxMor4aS4-NffW1QEWkmmRaC&authuser=jay.agg%40gmail.com&usp=drive_fs | B36: =IFERROR(__xludf.DUMMYFUNCTION("""COMPUTED_VALUE"""),"Food") -> Food | C36: =IFERROR(__xludf.DUMMYFUNCTION("""COMPUTED_VALUE"""),"Dry Fruit") -> Dry Fruit | D36: =IFERROR(__xludf.DUMMYFUNCTION("""COMPUTED_VALUE"""),"110*40*160 mm LB") -> 110*40*160 mm LB | E36: =IFERROR(__xludf.DUMMYFUNCTION("""COMPUTED_VALUE"""),4) -> 4 | F36: =IFERROR(__xludf.DUMMYFUNCTION("""COMPUTED_VALUE"""),1926) -> 1926 | G36: =IFERROR(__xludf.DUMMYFUNCTION("""COMPUTED_VALUE"""),18) -> 18 | H36: =IFERROR(__xludf.DUMMYFUNCTION("""COMPUTED_VALUE"""),25) -> 25 | I36: =IFERROR(__xludf.DUMMYFUNCTION("""COMPUTED_VALUE"""),100) -> 100 | M36: =IFERROR(__xludf.DUMMYFUNCTION("""COMPUTED_VALUE"""),0.16) -> 0.16 | N36: =IFERROR(__xludf.DUMMYFUNCTION("""COMPUTED_VALUE"""),1) -> 1 | P36: =IFERROR(__xludf.DUMMYFUNCTION("""COMPUTED_VALUE"""),"Offset") -> Offset | Q36: =IFERROR(__xludf.DUMMYFUNCTION("""COMPUTED_VALUE"""),"Packaging") -> Packaging | BC36: =IFERROR(__xludf.DUMMYFUNCTION("""COMPUTED_VALUE"""),"Packaging") -> Packaging | BD36: =IFERROR(__xludf.DUMMYFUNCTION("""COMPUTED_VALUE"""),"Hardware") -> Hardware | BS36: Art Card | BT36: Normal | BU36: 170 GSM | BV36: =#REF! -> #REF! | CD36: =BY36 -> 0 | CE36: =CD36 -> 0
A37: =IFERROR(__xludf.DUMMYFUNCTION("""COMPUTED_VALUE"""),"https://drive.google.com/open?id=1pIykPqoOxble5EREsGAMRPdA1QccQ1AJ&authuser=jay.agg%40gmail.com&usp=drive_fs") -> https://drive.google.com/open?id=1pIykPqoOxble5EREsGAMRPdA1QccQ1AJ&authuser=jay.agg%40gmail.com&usp=drive_fs | B37: =IFERROR(__xludf.DUMMYFUNCTION("""COMPUTED_VALUE"""),"Food") -> Food | C37: =IFERROR(__xludf.DUMMYFUNCTION("""COMPUTED_VALUE"""),"Cake Mix 500g") -> Cake Mix 500g | D37: =IFERROR(__xludf.DUMMYFUNCTION("""COMPUTED_VALUE"""),"140*45*180 mm") -> 140*45*180 mm | E37: =IFERROR(__xludf.DUMMYFUNCTION("""COMPUTED_VALUE"""),2) -> 2 | F37: =IFERROR(__xludf.DUMMYFUNCTION("""COMPUTED_VALUE"""),1926) -> 1926 | G37: =IFERROR(__xludf.DUMMYFUNCTION("""COMPUTED_VALUE"""),15.75) -> 15.75 | H37: =IFERROR(__xludf.DUMMYFUNCTION("""COMPUTED_VALUE"""),20.75) -> 20.75 | I37: =IFERROR(__xludf.DUMMYFUNCTION("""COMPUTED_VALUE"""),100) -> 100 | M37: =IFERROR(__xludf.DUMMYFUNCTION("""COMPUTED_VALUE"""),0.1) -> 0.1 | N37: =IFERROR(__xludf.DUMMYFUNCTION("""COMPUTED_VALUE"""),1) -> 1 | P37: =IFERROR(__xludf.DUMMYFUNCTION("""COMPUTED_VALUE"""),"Offset") -> Offset | Q37: =IFERROR(__xludf.DUMMYFUNCTION("""COMPUTED_VALUE"""),"Packaging") -> Packaging | BC37: =IFERROR(__xludf.DUMMYFUNCTION("""COMPUTED_VALUE"""),"Packaging") -> Packaging | BD37: =IFERROR(__xludf.DUMMYFUNCTION("""COMPUTED_VALUE"""),"Hawa Dhoop") -> Hawa Dhoop | BS37: Art Card | BT37: Normal | BU37: 220 GSM | BV37: =#REF! -> #REF! | CD37: =BY37 -> 0 | CE37: =CD37 -> 0
A38: =IFERROR(__xludf.DUMMYFUNCTION("""COMPUTED_VALUE"""),"https://drive.google.com/open?id=1pOGW1xVCuMnUABRqNq-5cbJ_ByoO8G5w&authuser=jay.agg%40gmail.com&usp=drive_fs") -> https://drive.google.com/open?id=1pOGW1xVCuMnUABRqNq-5cbJ_ByoO8G5w&authuser=jay.agg%40gmail.com&usp=drive_fs | B38: =IFERROR(__xludf.DUMMYFUNCTION("""COMPUTED_VALUE"""),"Food") -> Food | C38: =IFERROR(__xludf.DUMMYFUNCTION("""COMPUTED_VALUE"""),"Cake Mix 1kg") -> Cake Mix 1kg | D38: =IFERROR(__xludf.DUMMYFUNCTION("""COMPUTED_VALUE"""),"165*52*235 mm") -> 165*52*235 mm | E38: =IFERROR(__xludf.DUMMYFUNCTION("""COMPUTED_VALUE"""),2) -> 2 | F38: =IFERROR(__xludf.DUMMYFUNCTION("""COMPUTED_VALUE"""),1926) -> 1926 | G38: =IFERROR(__xludf.DUMMYFUNCTION("""COMPUTED_VALUE"""),19) -> 19 | H38: =IFERROR(__xludf.DUMMYFUNCTION("""COMPUTED_VALUE"""),26) -> 26 | I38: =IFERROR(__xludf.DUMMYFUNCTION("""COMPUTED_VALUE"""),100) -> 100 | M38: =IFERROR(__xludf.DUMMYFUNCTION("""COMPUTED_VALUE"""),0.1) -> 0.1 | N38: =IFERROR(__xludf.DUMMYFUNCTION("""COMPUTED_VALUE"""),1) -> 1 | P38: =IFERROR(__xludf.DUMMYFUNCTION("""COMPUTED_VALUE"""),"Offset") -> Offset | Q38: =IFERROR(__xludf.DUMMYFUNCTION("""COMPUTED_VALUE"""),"Packaging") -> Packaging | BC38: =IFERROR(__xludf.DUMMYFUNCTION("""COMPUTED_VALUE"""),"Packaging") -> Packaging | BD38: =IFERROR(__xludf.DUMMYFUNCTION("""COMPUTED_VALUE"""),"Hawan Box") -> Hawan Box | BS38: Art Card | BT38: Normal | BU38: 250 GSM | BV38: =#REF! -> #REF! | CD38: =BY38 -> 0 | CE38: =CD38 -> 0
